# plot_challenge

that one is quite difficult
and I met a question when I generate the scatter plot. 
'Tuple' is not callable.
And I restart the whole file, the bug disappered.
Weird.
